Workbook

Sheet Main
B1: Sq.ft. | C1: Sq.m.
A2: REU | B2: IN-CHEK2
A3: Chargeable Office Area | B3: 9515 | C3: =B3/10.764 -> 883.96507
A4: Agreement Start Date | B4: 46113
A5: Agreement End Date | B5: 47573
A6: Agreement Period | B6: =(B5-B4)/365 -> 4
A7: Quoted Rentals | B7: 120
A8: Quoted CAM | B8: 15.48
A9: Security Deposit | B9: 11418000
A10: Capex | B10: 2400000
A11: PM cost Over lease period
A12: Cost of Capital | B12: 0.15
A13: Imputed Interest | B13: 0.075
A14: Escalation Clause Rent | B14: 15% every 3 years
A15: Escalation Clause CAM | B15: 5% every years
A16: Maintenance Security Deposit (number of months)
A17: Addnl.Deposit -energy(Refundable) | B17: 500000

Sheet Security Deposit
B2: Security Deposit | C2: Interest | D2: Remark
A3: Fitout Deposit | B3: 0 | C3: =+B3*Main!B12/12*33.5 -> 0
A4: Security deposit | B4: =Main!B9 -> 11418000 | C4: =+B4*B9/12*D4 -> 10276200 | D4: ='Lease Rent'!H22 -> 72
A5: Additional deposit | B5: ='Lease Rent'!J31 * Main!B3 * Main!B16 -> 0 | C5: =+B5*Main!B12/12*D5 -> 0 | D5: =D4 -> 72
A6: Additional deposit (Electricity) | B6: =Main!B17 -> 500000 | C6: =+B6*B9*3 -> 225000
A7: Total | B7: =SUM(B3:B6) -> 11918000 | C7: =SUM(C3:C6) -> 10501200 | D7: =AVERAGE(D4:D6) -> 72
A8: Area sqft | B8: =Main!B3 -> 9515
A9: Rate for Carrying Cost | B9: =Main!B12 -> 0.15
A10: Term Period in Months | B10: ='Lease Rent'!H22 -> 72
A11: Rate per Sqft | C11: =C7/(B8*B10) -> 15.328429
A15: ARO working | B15: Per sqft | C15: Per sqmt
A16: Area (Sqft) | B16: =Main!B3 -> 9515
A17: ARO Rate (as on 30-09-2017) | B17: =IF(B16<50000,82.6,62.72) -> 82.6 | C17: =B17*10.764 -> 889.1064
A18: Total ARO Cost | B18: =B16*B17 -> 785939 | C18: =B18/B10 -> 10915.819
A19: Conversion Factor | B19: =C18/B16 -> 1.1472222

Sheet Lease Rent
G13: Rentals
G14: Year | H14: Months | I14: Rentals | J14: CAM | K14: Total
G15: 2026 | H15: =SUMIF($A$31:$A$1048576,$G15,$D$31:$D$102) -> 9 | I15: =SUMIF($A$31:$A$1048576,$G15,$K$31:$K$102) -> 10276200 | J15: =SUMIF($A$31:$A$1048576,$G15,$L$31:$L$102) -> 1325629.8 | K15: =I15+J15 -> 11601830
G16: =G15+1 -> 2027 | H16: =SUMIF($A$31:$A$1048576,$G16,$D$31:$D$102) -> 12 | I16: =SUMIF($A$31:$A$1048576,$G16,$K$31:$K$102) -> 13701600 | J16: =SUMIF($A$31:$A$1048576,$G16,$L$31:$L$102) -> 1826423.3 | K16: =I16+J16 -> 15528023
G17: =G16+1 -> 2028 | H17: =SUMIF($A$31:$A$1048576,$G17,$D$31:$D$102) -> 12 | I17: =SUMIF($A$31:$A$1048576,$G17,$K$31:$K$102) -> 13701600 | J17: =SUMIF($A$31:$A$1048576,$G17,$L$31:$L$102) -> 1917744.4 | K17: =I17+J17 -> 15619344
G18: =G17+1 -> 2029 | H18: =SUMIF($A$31:$A$1048576,$G18,$D$31:$D$102) -> 12 | I18: =SUMIF($A$31:$A$1048576,$G18,$K$31:$K$102) -> 15243030 | J18: =SUMIF($A$31:$A$1048576,$G18,$L$31:$L$102) -> 2021751.1 | K18: =I18+J18 -> 17264781
G19: =G18+1 -> 2030 | H19: =SUMIF($A$31:$A$1048576,$G19,$D$31:$D$102) -> 12 | I19: =SUMIF($A$31:$A$1048576,$G19,$K$31:$K$102) -> 15756840 | J19: =SUMIF($A$31:$A$1048576,$G19,$L$31:$L$102) -> 2114313.2 | K19: =I19+J19 -> 17871153
G20: =G19+1 -> 2031 | H20: =SUMIF($A$31:$A$1048576,$G20,$D$31:$D$102) -> 12 | I20: =SUMIF($A$31:$A$1048576,$G20,$K$31:$K$102) -> 15756840 | J20: =SUMIF($A$31:$A$1048576,$G20,$L$31:$L$102) -> 2220028.9 | K20: =I20+J20 -> 17976869
G21: =G20+1 -> 2032 | H21: =SUMIF($A$31:$A$1048576,$G21,$D$31:$D$102) -> 3 | I21: =SUMIF($A$31:$A$1048576,$G21,$K$31:$K$102) -> 3939210 | J21: =SUMIF($A$31:$A$1048576,$G21,$L$31:$L$102) -> 563958.96 | K21: =I21+J21 -> 4503169
H22: =SUM(H15:H21) -> 72 | I22: =SUM(I15:I21) -> 88375320 | J22: =SUM(J15:J21) -> 11989850 | K22: =SUM(K15:K21) -> 1.0036517e+08
A30: Year | B30: From | C30: To | D30: Months | E30: Area in SQF | F30: Area in SQM | G30: Escalation | H30: Rental | I30: Car Parks per # | J30: CAM | K30: Rental SQM | L30: CAM SQM | M30: Total | N30: Rentals | O30: CAM
A31: 2026 | B31: 46023 | C31: =B31+30 -> 46053 | D31: 1 | E31: =Main!B3 -> 9515 | F31: =Main!C3 -> 883.96507 | H31: =120 -> 120 | J31: =15.48 -> 15.48 | K31: =H31*E31 -> 1141800 | L31: =J31*E31 -> 147292.2 | M31: =I31+K31+L31 -> 1289092.2
A32: =A31 -> 2026 | B32: =C31+1 -> 46054 | C32: =B32+30-3 -> 46081 | D32: 1 | E32: 9515 | F32: 883.96507 | H32: 120 | J32: 15.48 | K32: =H32*E32 -> 1141800 | L32: =J32*E32 -> 147292.2 | M32: =I32+K32+L32 -> 1289092.2
A33: =A32 -> 2026 | B33: =C32+1 -> 46082 | C33: =B33+30 -> 46112 | D33: 1 | E33: =E32 -> 9515 | F33: =F32 -> 883.96507 | H33: 120 | J33: =J32 -> 15.48 | K33: =H33*E33 -> 1141800 | L33: =J33*E33 -> 147292.2 | M33: =I33+K33+L33 -> 1289092.2
A34: =A33 -> 2026 | B34: =C33+1 -> 46113 | C34: =B34+30-1 -> 46142 | D34: 1 | E34: =E33 -> 9515 | F34: =F33 -> 883.96507 | H34: 120 | J34: =J33 -> 15.48 | K34: =H34*E34 -> 1141800 | L34: =J34*E34 -> 147292.2 | M34: =I34+K34+L34 -> 1289092.2
A35: =A34 -> 2026 | B35: =C34+1 -> 46143 | C35: =B35+30 -> 46173 | D35: 1 | E35: =E34 -> 9515 | F35: =F34 -> 883.96507 | H35: 120 | J35: =J34 -> 15.48 | K35: =H35*E35 -> 1141800 | L35: =J35*E35 -> 147292.2 | M35: =I35+K35+L35 -> 1289092.2
A36: =A35 -> 2026 | B36: =C35+1 -> 46174 | C36: =B36+30-1 -> 46203 | D36: 1 | E36: =E35 -> 9515 | F36: =F35 -> 883.96507 | H36: 120 | J36: =J35 -> 15.48 | K36: =H36*E36 -> 1141800 | L36: =J36*E36 -> 147292.2 | M36: =I36+K36+L36 -> 1289092.2
A37: =A36 -> 2026 | B37: =C36+1 -> 46204 | C37: =B37+30-1 -> 46233 | D37: 1 | E37: =E36 -> 9515 | F37: =F36 -> 883.96507 | H37: 120 | J37: =J36 -> 15.48 | K37: =H37*E37 -> 1141800 | L37: =J37*E37 -> 147292.2 | M37: =I37+K37+L37 -> 1289092.2
A38: =A37 -> 2026 | B38: =C37+1 -> 46234 | C38: =B38+30 -> 46264 | D38: 1 | E38: =E37 -> 9515 | F38: =F37 -> 883.96507 | H38: 120 | J38: =J37 -> 15.48 | K38: =H38*E38 -> 1141800 | L38: =J38*E38 -> 147292.2 | M38: =I38+K38+L38 -> 1289092.2
A39: =A38 -> 2026 | B39: =C38+1 -> 46265 | C39: =B39+30 -> 46295 | D39: 1 | E39: =E38 -> 9515 | F39: =F38 -> 883.96507 | H39: 120 | J39: =J38 -> 15.48 | K39: =H39*E39 -> 1141800 | L39: =J39*E39 -> 147292.2 | M39: =I39+K39+L39 -> 1289092.2 | N39: =SUM(K31:K39) -> 10276200 | O39: =SUM(L31:L39) -> 1325629.8
A40: =A39+1 -> 2027 | B40: =C39+1 -> 46296 | C40: =B40+30 -> 46326 | D40: 1 | E40: =E39 -> 9515 | F40: =F39 -> 883.96507 | H40: 120 | J40: =J39 -> 15.48 | K40: =H40*E40 -> 1141800 | L40: =J40*E40 -> 147292.2 | M40: =I40+K40+L40 -> 1289092.2
A41: =A40 -> 2027 | B41: =C40+1 -> 46327 | C41: =B41+30-1 -> 46356 | D41: 1 | E41: =E40 -> 9515 | F41: =F40 -> 883.96507 | H41: 120 | J41: =J40 -> 15.48 | K41: =H41*E41 -> 1141800 | L41: =J41*E41 -> 147292.2 | M41: =I41+K41+L41 -> 1289092.2
A42: =A41 -> 2027 | B42: =C41+1 -> 46357 | C42: =B42+30 -> 46387 | D42: 1 | E42: =E41 -> 9515 | F42: =F41 -> 883.96507 | H42: 120 | J42: =J41 -> 15.48 | K42: =H42*E42 -> 1141800 | L42: =J42*E42 -> 147292.2 | M42: =I42+K42+L42 -> 1289092.2
A43: =A42 -> 2027 | B43: =C42+1 -> 46388 | C43: =B43+30 -> 46418 | D43: 1 | E43: =E42 -> 9515 | F43: =F42 -> 883.96507 | H43: 120 | J43: =J42 -> 15.48 | K43: =H43*E43 -> 1141800 | L43: =J43*E43 -> 147292.2 | M43: =I43+K43+L43 -> 1289092.2
A44: =A43 -> 2027 | B44: =C43+1 -> 46419 | C44: =B44+30-3 -> 46446 | D44: 1 | E44: =E43 -> 9515 | F44: =F43 -> 883.96507 | H44: 120 | J44: =J43*1.05 -> 16.254 | K44: =H44*E44 -> 1141800 | L44: =J44*E44 -> 154656.81 | M44: =I44+K44+L44 -> 1296456.8
A45: =A44 -> 2027 | B45: =C44+1 -> 46447 | C45: =B45+30 -> 46477 | D45: 1 | E45: =E44 -> 9515 | F45: =F44 -> 883.96507 | H45: 120 | J45: =J44 -> 16.254 | K45: =H45*E45 -> 1141800 | L45: =J45*E45 -> 154656.81 | M45: =I45+K45+L45 -> 1296456.8
A46: =A45 -> 2027 | B46: =C45+1 -> 46478 | C46: =B46+30-1 -> 46507 | D46: 1 | E46: =E45 -> 9515 | F46: =F45 -> 883.96507 | H46: 120 | J46: =J45 -> 16.254 | K46: =H46*E46 -> 1141800 | L46: =J46*E46 -> 154656.81 | M46: =I46+K46+L46 -> 1296456.8
A47: =A46 -> 2027 | B47: =C46+1 -> 46508 | C47: =B47+30 -> 46538 | D47: 1 | E47: =E46 -> 9515 | F47: =F46 -> 883.96507 | H47: 120 | J47: =J46 -> 16.254 | K47: =H47*E47 -> 1141800 | L47: =J47*E47 -> 154656.81 | M47: =I47+K47+L47 -> 1296456.8
A48: =A47 -> 2027 | B48: =C47+1 -> 46539 | C48: =B48+30-1 -> 46568 | D48: 1 | E48: =E47 -> 9515 | F48: =F47 -> 883.96507 | H48: 120 | J48: =J47 -> 16.254 | K48: =H48*E48 -> 1141800 | L48: =J48*E48 -> 154656.81 | M48: =I48+K48+L48 -> 1296456.8
A49: =A48 -> 2027 | B49: =C48+1 -> 46569 | C49: =B49+30 -> 46599 | D49: 1 | E49: =E48 -> 9515 | F49: =F48 -> 883.96507 | H49: 120 | J49: =J48 -> 16.254 | K49: =H49*E49 -> 1141800 | L49: =J49*E49 -> 154656.81 | M49: =I49+K49+L49 -> 1296456.8
A50: =A49 -> 2027 | B50: =C49+1 -> 46600 | C50: =B50+30 -> 46630 | D50: 1 | E50: =E49 -> 9515 | F50: =F49 -> 883.96507 | H50: 120 | J50: =J49 -> 16.254 | K50: =H50*E50 -> 1141800 | L50: =J50*E50 -> 154656.81 | M50: =I50+K50+L50 -> 1296456.8
A51: =A50 -> 2027 | B51: =C50+1 -> 46631 | C51: =B51+30-1 -> 46660 | D51: 1 | E51: =E50 -> 9515 | F51: =F50 -> 883.96507 | H51: 120 | J51: =J50 -> 16.254 | K51: =H51*E51 -> 1141800 | L51: =J51*E51 -> 154656.81 | M51: =I51+K51+L51 -> 1296456.8 | N51: =SUM(K40:K51) -> 13701600 | O51: =SUM(L40:L51) -> 1826423.3
A52: =A51+1 -> 2028 | B52: =C51+1 -> 46661 | C52: =B52+30 -> 46691 | D52: 1 | E52: =E51 -> 9515 | F52: =F51 -> 883.96507 | H52: 120 | J52: =J51 -> 16.254 | K52: =H52*E52 -> 1141800 | L52: =J52*E52 -> 154656.81 | M52: =I52+K52+L52 -> 1296456.8
A53: =A52 -> 2028 | B53: =C52+1 -> 46692 | C53: =B53+30-1 -> 46721 | D53: 1 | E53: =E52 -> 9515 | F53: =F52 -> 883.96507 | H53: 120 | J53: =J52 -> 16.254 | K53: =H53*E53 -> 1141800 | L53: =J53*E53 -> 154656.81 | M53: =I53+K53+L53 -> 1296456.8
A54: =A53 -> 2028 | B54: =C53+1 -> 46722 | C54: =B54+30 -> 46752 | D54: 1 | E54: =E53 -> 9515 | F54: =F53 -> 883.96507 | H54: 120 | J54: =J53 -> 16.254 | K54: =H54*E54 -> 1141800 | L54: =J54*E54 -> 154656.81 | M54: =I54+K54+L54 -> 1296456.8
A55: =A54 -> 2028 | B55: =C54+1 -> 46753 | C55: =B55+30 -> 46783 | D55: 1 | E55: =E54 -> 9515 | F55: =F54 -> 883.96507 | H55: 120 | J55: =J54 -> 16.254 | K55: =H55*E55 -> 1141800 | L55: =J55*E55 -> 154656.81 | M55: =I55+K55+L55 -> 1296456.8
A56: =A55 -> 2028 | B56: =C55+1 -> 46784 | C56: =B56+30-2 -> 46812 | D56: 1 | E56: =E55 -> 9515 | F56: =F55 -> 883.96507 | H56: 120 | J56: =J55*1.05 -> 17.0667 | K56: =H56*E56 -> 1141800 | L56: =J56*E56 -> 162389.65 | M56: =I56+K56+L56 -> 1304189.7
A57: =A56 -> 2028 | B57: =C56+1 -> 46813 | C57: =B57+30 -> 46843 | D57: 1 | E57: =E56 -> 9515 | F57: =F56 -> 883.96507 | H57: 120 | J57: =J56 -> 17.0667 | K57: =H57*E57 -> 1141800 | L57: =J57*E57 -> 162389.65 | M57: =I57+K57+L57 -> 1304189.7
A58: =A57 -> 2028 | B58: =C57+1 -> 46844 | C58: =B58+30-1 -> 46873 | D58: 1 | E58: =E57 -> 9515 | F58: =F57 -> 883.96507 | H58: 120 | J58: =J57 -> 17.0667 | K58: =H58*E58 -> 1141800 | L58: =J58*E58 -> 162389.65 | M58: =I58+K58+L58 -> 1304189.7
A59: =A58 -> 2028 | B59: =C58+1 -> 46874 | C59: =B59+30 -> 46904 | D59: 1 | E59: =E58 -> 9515 | F59: =F58 -> 883.96507 | H59: 120 | J59: =J58 -> 17.0667 | K59: =H59*E59 -> 1141800 | L59: =J59*E59 -> 162389.65 | M59: =I59+K59+L59 -> 1304189.7
...
